Afin d'exécuter le script (main.py) correctement, il est recommandé, dans l'ordre :

1. d'avoir déjà installé Python dans une version >= 3.4

        => dans une ligne de terminal, taper :
        python3 --version

        Si vous recevez un message d'erreur indiquant que Python est introuvable,
        ou un message similaire, il est probable que votre installation de Python
        soit incorrecte ou manquante. Dans ce cas, vous devez télécharger et installer
        la dernière version de Python avant de continuer.

        Sinon vous devrier voir s'afficher Python 3.4...

2. de créer un environnement virtuel à la racine du dossier projet :

        => dans une ligne de terminal, viser le dossier et taper :
        python3 -m venv env

3. d'activer l'environnement virtuel créé précédemment :

        => dans une ligne de terminal, taper :
        source env/bin/activate

4. d'installer les paquets Python suivants dans l'environnement virtuel activé précédemment :

        => dans une ligne de terminal, taper :
        pip3 install beautifulsoup4
        pip3 install requests

        nb : pour plus d'informations, consulter PyPi.org.

5. de vérifier la bonne installation des paquets Python :

        => dans une ligne de terminal, taper :
        pip3 freeze

        Vous devriez obtenir :  beautifulsoup4==4.9.3
                                bs4==0.0.1
                                certifi==2020.12.5
                                chardet==4.0.0
                                idna==2.10
                                requests==2.25.1
                                soupsieve==2.1
                                urllib3==1.26.2

        nb : les paquets python non mentionnés avant sont inclus
        (requires et required by) dans ceux installés au point 4.

6. d'exécuter le script :

        => dans une ligne de terminal, taper :
        python3 main.py

        nb : si pour une raison vous devez relancer l'exécution du script,
        veillez à bien supprimer le dossier export généré auparavant,
        sinon le message d'erreur ci-dessous s'affiche :
        Traceback (most recent call last):
        File "main.py", line 5, in <module>
        os.mkdir('export/')
        FileExistsError: [Errno 17] File exists: 'export/'

7. d'attendre la fin de l'exécution du script avant de consulter les données "scrappées"
    dans le dossier export/ généré.






